Workbook

Sheet Detail quantitatif fondation
A1: AO N° :
C3: Construction de locaux et travaux de réaménagement à la mine Youssoufia
E5: Détail Quantitatif Métré
A6: N° | B6: Désignation, détail de calcul, croquis, principe et justificatif | G6: U | H6: N | I6: Longueur | J6: largeur | K6: Hauteur / épaisseur | L6: Qté partielle | M6: Qté Total des Métrés
A8: 1 | B8: A- ETUDES TECHNIQUES, ESSAIS, CONTROLES ET RECEPTIONS
B9: Etude suivant descriptif (géotechnique, technique, formulations bétons, essais et contrôles, réceptions, récolement)
G10: f | H10: 1 | M10: 1
A11: 3 | B11: B- GROS ŒUVRES et maconnerie
B12: Terrassement en fouilles, en tranchées ou en plein masse y compris décapage de la terre végétale
N13: H/ bon sol + terre végétale $$$
N14: 1.48
B15: axe | C15: fill
B16: A | C16: 1-6 | G16: M3 | H16: 1 | I16: 25.4 | J16: 1.6 | K16: =$N$14 | L16: =K16*J16*I16*H16
B17: F | C17: 1-6 | G17: M3 | H17: 1 | I17: 25.4 | J17: 1.6 | K17: =$N$14+0.5 | L17: =K17*J17*I17*H17
B18: A-F | C18: 1 | G18: M3 | H18: 1 | I18: 11.4 | J18: 1.6 | K18: =$N$14 | L18: =K18*J18*I18*H18
B19: A-F | C19: 6 | G19: M3 | H19: 1 | I19: 11.4 | J19: 1.6 | K19: =$N$14 | L19: =K19*J19*I19*H19
B20: C-D | C20: 2 | G20: M3 | H20: 1 | I20: 2.75 | J20: 1.6 | K20: =$N$14+0.5 | L20: =K20*J20*I20*H20
B21: C-D | C21: 3 | G21: M3 | H21: 1 | I21: 2.75 | J21: 1.6 | K21: =$N$14 | L21: =K21*J21*I21*H21
B22: C-D | C22: 4 | G22: M3 | H22: 1 | I22: 2.75 | J22: 1.6 | K22: =$N$14 | L22: =K22*J22*I22*H22
B23: C-D | C23: 5 | G23: M3 | H23: 1 | I23: 2.75 | J23: 1.6 | K23: =$N$14 | L23: =K23*J23*I23*H23
A24: total | M24: =SUM(L16:L23)
A25: 15 | B25: Béton de propreté
A26: pour semelle isolee
B27: axe | C27: fill
A28: S1 | B28: A | C28: 1 | D28: 1 | E28: 1 | F28: 0.25 | G28: M3 | H28: 1 | I28: =D28 | J28: =E28 | K28: 0.1 | L28: =H28*I28*J28*K28
A29: S4 | B29: A | C29: 2 | D29: 1.5 | E29: 1.5 | F29: 0.4 | G29: M3 | H29: 1 | I29: =D29 | J29: =E29 | K29: 0.1 | L29: =H29*I29*J29*K29
A30: S4 | B30: A | C30: 4 | D30: 1.5 | E30: 1.5 | F30: 0.4 | G30: M3 | H30: 1 | I30: =D30 | J30: =E30 | K30: 0.1 | L30: =H30*I30*J30*K30
A31: S2 | B31: A | C31: 5 | D31: 1.1 | E31: 1.1 | F31: 0.25 | G31: M3 | H31: 1 | I31: =D31 | J31: =E31 | K31: 0.1 | L31: =H31*I31*J31*K31
A32: S3 | B32: A | C32: 6 | D32: 1.2 | E32: 1.2 | F32: 0.3 | G32: M3 | H32: 1 | I32: =D32 | J32: =E32 | K32: 0.1 | L32: =H32*I32*J32*K32
A33: S3 | B33: A | C33: 7 | D33: 1.2 | E33: 1.2 | F33: 0.3 | G33: M3 | H33: 1 | I33: =D33 | J33: =E33 | K33: 0.1 | L33: =H33*I33*J33*K33
A34: S4 | B34: D | C34: 1 | D34: 1.5 | E34: 1.5 | F34: 0.4 | G34: M3 | H34: 1 | I34: =D34 | J34: =E34 | K34: 0.1 | L34: =H34*I34*J34*K34
A35: total | M35: =SUM(L28:L34)
A36: pour longrines
A37: axe | B37: fill | C37: Nom
B38: C | C38: 5-6 | D38: LG | G38: M3 | H38: 1 | I38: 4.78 | J38: 0.4 | K38: 0.1 | L38: =K38*J38*I38*H38
B39: C | C39: 6-7 | D39: LG | G39: M3 | H39: 1 | I39: 2.65 | J39: 0.4 | K39: 0.1 | L39: =K39*J39*I39*H39
B40: C | C40: 7-8 | D40: LG | G40: M3 | H40: 1 | I40: 4.6 | J40: 0.4 | K40: 0.1 | L40: =K40*J40*I40*H40
B41: D | C41: 1-2 | D41: LG2 | G41: M3 | H41: 1 | I41: 2.48 | J41: 0.4 | K41: 0.1 | L41: =K41*J41*I41*H41
B42: D | C42: 2-3 | D42: LG2 | G42: M3 | H42: 1 | I42: =3.7 | J42: 0.4 | K42: 0.1 | L42: =K42*J42*I42*H42
B43: D | C43: 3-4 | D43: LG2 | G43: M3 | H43: 1 | I43: =3.7 | J43: 0.4 | K43: 0.1 | L43: =K43*J43*I43*H43
...

Sheet Armatures
A1: AO N° :
C3: Construction de locaux et travaux de réaménagement à la mine Youssoufia
E5: Détail Quantitatif Métré
A6: N° | B6: Désignation, détail de calcul, croquis, principe et justificatif | G6: U | H6: N | I6: Longueur | J6: largeur | K6: Hauteur / épaisseur | L6: Qté partielle | M6: Qté Total des Métrés
A8: 21 | B8: Armature pour béton armé en fondation et en élévation
A9: semelle isolee
A10: ax | G10: 2 | H10: 6 | I10: 12 | J10: =1.0-0.05+34*I10/1000 | K10: =IF(I10=6,G10*H10*J10,"") | L10: =IF(I10=8,G10*H10*J10,"") | M10: =IF(I10=10,G10*H10*J10,"") | N10: =IF(I10=12,G10*H10*J10,"") | O10: =IF(I10=14,G10*H10*J10,"") | P10: =IF(I10=16,G10*H10*J10,"") | Q10: =IF(I10=20,G10*H10*J10,"") | R10: =IF(I10=25,G10*H10*J10,"") | S10: =IF(I10=32,G10*H10*J10,"")
A11: ay | G11: 2 | H11: 6 | I11: 12 | J11: =1.0-0.05+34*I11/1000 | K11: =IF(I11=6,G11*H11*J11,"") | L11: =IF(I11=8,G11*H11*J11,"") | M11: =IF(I11=10,G11*H11*J11,"") | N11: =IF(I11=12,G11*H11*J11,"") | O11: =IF(I11=14,G11*H11*J11,"") | P11: =IF(I11=16,G11*H11*J11,"") | Q11: =IF(I11=20,G11*H11*J11,"") | R11: =IF(I11=25,G11*H11*J11,"") | S11: =IF(I11=32,G11*H11*J11,"")
A12: ax | G12: 1 | H12: 7 | I12: 12 | J12: =1.1-0.05+34*I12/1000 | K12: =IF(I12=6,G12*H12*J12,"") | L12: =IF(I12=8,G12*H12*J12,"") | M12: =IF(I12=10,G12*H12*J12,"") | N12: =IF(I12=12,G12*H12*J12,"") | O12: =IF(I12=14,G12*H12*J12,"") | P12: =IF(I12=16,G12*H12*J12,"") | Q12: =IF(I12=20,G12*H12*J12,"") | R12: =IF(I12=25,G12*H12*J12,"") | S12: =IF(I12=32,G12*H12*J12,"")
A13: ay | G13: 1 | H13: 7 | I13: 12 | J13: =1.1-0.05+34*I13/1000 | K13: =IF(I13=6,G13*H13*J13,"") | L13: =IF(I13=8,G13*H13*J13,"") | M13: =IF(I13=10,G13*H13*J13,"") | N13: =IF(I13=12,G13*H13*J13,"") | O13: =IF(I13=14,G13*H13*J13,"") | P13: =IF(I13=16,G13*H13*J13,"") | Q13: =IF(I13=20,G13*H13*J13,"") | R13: =IF(I13=25,G13*H13*J13,"") | S13: =IF(I13=32,G13*H13*J13,"")
A14: ax | G14: 8 | H14: 8 | I14: 12 | J14: =1.2-0.05+34*I14/1000 | K14: =IF(I14=6,G14*H14*J14,"") | L14: =IF(I14=8,G14*H14*J14,"") | M14: =IF(I14=10,G14*H14*J14,"") | N14: =IF(I14=12,G14*H14*J14,"") | O14: =IF(I14=14,G14*H14*J14,"") | P14: =IF(I14=16,G14*H14*J14,"") | Q14: =IF(I14=20,G14*H14*J14,"") | R14: =IF(I14=25,G14*H14*J14,"") | S14: =IF(I14=32,G14*H14*J14,"")
A15: ay | G15: 8 | H15: 8 | I15: 12 | J15: =1.2-0.05+34*I15/1000 | K15: =IF(I15=6,G15*H15*J15,"") | L15: =IF(I15=8,G15*H15*J15,"") | M15: =IF(I15=10,G15*H15*J15,"") | N15: =IF(I15=12,G15*H15*J15,"") | O15: =IF(I15=14,G15*H15*J15,"") | P15: =IF(I15=16,G15*H15*J15,"") | Q15: =IF(I15=20,G15*H15*J15,"") | R15: =IF(I15=25,G15*H15*J15,"") | S15: =IF(I15=32,G15*H15*J15,"")
A16: ax | G16: 9 | H16: 11 | I16: 12 | J16: =1.5-0.05+34*I16/1000 | K16: =IF(I16=6,G16*H16*J16,"") | L16: =IF(I16=8,G16*H16*J16,"") | M16: =IF(I16=10,G16*H16*J16,"") | N16: =IF(I16=12,G16*H16*J16,"") | O16: =IF(I16=14,G16*H16*J16,"") | P16: =IF(I16=16,G16*H16*J16,"") | Q16: =IF(I16=20,G16*H16*J16,"") | R16: =IF(I16=25,G16*H16*J16,"") | S16: =IF(I16=32,G16*H16*J16,"")
A17: ay | G17: 9 | H17: 11 | I17: 12 | J17: =1.5-0.05+34*I17/1000 | K17: =IF(I17=6,G17*H17*J17,"") | L17: =IF(I17=8,G17*H17*J17,"") | M17: =IF(I17=10,G17*H17*J17,"") | N17: =IF(I17=12,G17*H17*J17,"") | O17: =IF(I17=14,G17*H17*J17,"") | P17: =IF(I17=16,G17*H17*J17,"") | Q17: =IF(I17=20,G17*H17*J17,"") | R17: =IF(I17=25,G17*H17*J17,"") | S17: =IF(I17=32,G17*H17*J17,"")
A18: ax | G18: 3 | H18: 11 | I18: 12 | J18: =1.5-0.05+34*I18/1000 | K18: =IF(I18=6,G18*H18*J18,"") | L18: =IF(I18=8,G18*H18*J18,"") | M18: =IF(I18=10,G18*H18*J18,"") | N18: =IF(I18=12,G18*H18*J18,"") | O18: =IF(I18=14,G18*H18*J18,"") | P18: =IF(I18=16,G18*H18*J18,"") | Q18: =IF(I18=20,G18*H18*J18,"") | R18: =IF(I18=25,G18*H18*J18,"") | S18: =IF(I18=32,G18*H18*J18,"")
A19: ay | G19: 3 | H19: 11 | I19: 12 | J19: =1.5-0.05+34*I19/1000 | K19: =IF(I19=6,G19*H19*J19,"") | L19: =IF(I19=8,G19*H19*J19,"") | M19: =IF(I19=10,G19*H19*J19,"") | N19: =IF(I19=12,G19*H19*J19,"") | O19: =IF(I19=14,G19*H19*J19,"") | P19: =IF(I19=16,G19*H19*J19,"") | Q19: =IF(I19=20,G19*H19*J19,"") | R19: =IF(I19=25,G19*H19*J19,"") | S19: =IF(I19=32,G19*H19*J19,"")
A20: total | M20: =SUM(L10:L19)
A21: fût poteau
T22: 1.4
E23: P1 | K23: =IF(I23=6,G23*H23*J23,"") | L23: =IF(I23=8,G23*H23*J23,"") | M23: =IF(I23=10,G23*H23*J23,"") | N23: =IF(I23=12,G23*H23*J23,"") | O23: =IF(I23=14,G23*H23*J23,"") | P23: =IF(I23=16,G23*H23*J23,"") | Q23: =IF(I23=20,G23*H23*J23,"") | R23: =IF(I23=25,G23*H23*J23,"") | S23: =IF(I23=32,G23*H23*J23,"")
A24: ARM LONG | G24: 12 | H24: 4 | I24: 14 | J24: =($T$22-0.1-0.05)+70*I24/1000+18*I24/1000 | K24: =IF(I24=6,G24*H24*J24,"") | L24: =IF(I24=8,G24*H24*J24,"") | M24: =IF(I24=10,G24*H24*J24,"") | N24: =IF(I24=12,G24*H24*J24,"") | O24: =IF(I24=14,G24*H24*J24,"") | P24: =IF(I24=16,G24*H24*J24,"") | Q24: =IF(I24=20,G24*H24*J24,"") | R24: =IF(I24=25,G24*H24*J24,"") | S24: =IF(I24=32,G24*H24*J24,"")
A25: ARM LONG | G25: 12 | H25: 2 | I25: 14 | J25: =($T$22-0.1-0.05)+70*I25/1000+18*I25/1000 | K25: =IF(I25=6,G25*H25*J25,"") | L25: =IF(I25=8,G25*H25*J25,"") | M25: =IF(I25=10,G25*H25*J25,"") | N25: =IF(I25=12,G25*H25*J25,"") | O25: =IF(I25=14,G25*H25*J25,"") | P25: =IF(I25=16,G25*H25*J25,"") | Q25: =IF(I25=20,G25*H25*J25,"") | R25: =IF(I25=25,G25*H25*J25,"") | S25: =IF(I25=32,G25*H25*J25,"")
A26: CADRE | G26: 12 | H26: =ROUNDUP(1.2/0.15,0)+2 | I26: 6 | J26: =(2*(0.25+0.35)-0.05+20.5*I26/1000) | K26: =IF(I26=6,G26*H26*J26,"") | L26: =IF(I26=8,G26*H26*J26,"") | M26: =IF(I26=10,G26*H26*J26,"") | N26: =IF(I26=12,G26*H26*J26,"") | O26: =IF(I26=14,G26*H26*J26,"") | P26: =IF(I26=16,G26*H26*J26,"") | Q26: =IF(I26=20,G26*H26*J26,"") | R26: =IF(I26=25,G26*H26*J26,"") | S26: =IF(I26=32,G26*H26*J26,"")
A27: EPINGLE | G27: 12 | H27: =ROUNDUP(1.2/0.15,0)+2 | I27: 6 | J27: =0.25-0.05+22*I27/1000 | K27: =IF(I27=6,G27*H27*J27,"") | L27: =IF(I27=8,G27*H27*J27,"") | M27: =IF(I27=10,G27*H27*J27,"") | N27: =IF(I27=12,G27*H27*J27,"") | O27: =IF(I27=14,G27*H27*J27,"") | P27: =IF(I27=16,G27*H27*J27,"") | Q27: =IF(I27=20,G27*H27*J27,"") | R27: =IF(I27=25,G27*H27*J27,"") | S27: =IF(I27=32,G27*H27*J27,"")
E28: P2 | K28: =IF(I28=6,G28*H28*J28,"") | L28: =IF(I28=8,G28*H28*J28,"") | M28: =IF(I28=10,G28*H28*J28,"") | N28: =IF(I28=12,G28*H28*J28,"") | O28: =IF(I28=14,G28*H28*J28,"") | P28: =IF(I28=16,G28*H28*J28,"") | Q28: =IF(I28=20,G28*H28*J28,"") | R28: =IF(I28=25,G28*H28*J28,"") | S28: =IF(I28=32,G28*H28*J28,"")
A29: ARM LONG | G29: 5 | H29: 4 | I29: 14 | J29: =($T$22-0.1-0.05)+70*I29/1000+18*I29/1000 | K29: =IF(I29=6,G29*H29*J29,"") | L29: =IF(I29=8,G29*H29*J29,"") | M29: =IF(I29=10,G29*H29*J29,"") | N29: =IF(I29=12,G29*H29*J29,"") | O29: =IF(I29=14,G29*H29*J29,"") | P29: =IF(I29=16,G29*H29*J29,"") | Q29: =IF(I29=20,G29*H29*J29,"") | R29: =IF(I29=25,G29*H29*J29,"") | S29: =IF(I29=32,G29*H29*J29,"")
A30: ARM LONG | G30: 5 | H30: 2 | I30: 14 | J30: =($T$22-0.1-0.05)+70*I30/1000+18*I30/1000 | K30: =IF(I30=6,G30*H30*J30,"") | L30: =IF(I30=8,G30*H30*J30,"") | M30: =IF(I30=10,G30*H30*J30,"") | N30: =IF(I30=12,G30*H30*J30,"") | O30: =IF(I30=14,G30*H30*J30,"") | P30: =IF(I30=16,G30*H30*J30,"") | Q30: =IF(I30=20,G30*H30*J30,"") | R30: =IF(I30=25,G30*H30*J30,"") | S30: =IF(I30=32,G30*H30*J30,"")
A31: CADRE | G31: 5 | H31: =ROUNDUP(1.2/0.15,0)+2 | I31: 6 | J31: =(2*(0.4+0.4)-0.05+20.5*I31/1000) | K31: =IF(I31=6,G31*H31*J31,"") | L31: =IF(I31=8,G31*H31*J31,"") | M31: =IF(I31=10,G31*H31*J31,"") | N31: =IF(I31=12,G31*H31*J31,"") | O31: =IF(I31=14,G31*H31*J31,"") | P31: =IF(I31=16,G31*H31*J31,"") | Q31: =IF(I31=20,G31*H31*J31,"") | R31: =IF(I31=25,G31*H31*J31,"") | S31: =IF(I31=32,G31*H31*J31,"")
A32: EPINGLE | G32: 5 | H32: =ROUNDUP(1.2/0.15,0)+2 | I32: 6 | J32: =0.4-0.05+22*I32/1000 | K32: =IF(I32=6,G32*H32*J32,"") | L32: =IF(I32=8,G32*H32*J32,"") | M32: =IF(I32=10,G32*H32*J32,"") | N32: =IF(I32=12,G32*H32*J32,"") | O32: =IF(I32=14,G32*H32*J32,"") | P32: =IF(I32=16,G32*H32*J32,"") | Q32: =IF(I32=20,G32*H32*J32,"") | R32: =IF(I32=25,G32*H32*J32,"") | S32: =IF(I32=32,G32*H32*J32,"")
E33: P3 | K33: =IF(I33=6,G33*H33*J33,"") | L33: =IF(I33=8,G33*H33*J33,"") | M33: =IF(I33=10,G33*H33*J33,"") | N33: =IF(I33=12,G33*H33*J33,"") | O33: =IF(I33=14,G33*H33*J33,"") | P33: =IF(I33=16,G33*H33*J33,"") | Q33: =IF(I33=20,G33*H33*J33,"") | R33: =IF(I33=25,G33*H33*J33,"") | S33: =IF(I33=32,G33*H33*J33,"")
A34: ARM LONG | G34: 4 | H34: 4 | I34: 14 | J34: =($T$22-0.1-0.05)+70*I34/1000+18*I34/1000 | K34: =IF(I34=6,G34*H34*J34,"") | L34: =IF(I34=8,G34*H34*J34,"") | M34: =IF(I34=10,G34*H34*J34,"") | N34: =IF(I34=12,G34*H34*J34,"") | O34: =IF(I34=14,G34*H34*J34,"") | P34: =IF(I34=16,G34*H34*J34,"") | Q34: =IF(I34=20,G34*H34*J34,"") | R34: =IF(I34=25,G34*H34*J34,"") | S34: =IF(I34=32,G34*H34*J34,"")
A35: ARM LONG | G35: 4 | H35: 2 | I35: 14 | J35: =($T$22-0.1-0.05)+70*I35/1000+18*I35/1000 | K35: =IF(I35=6,G35*H35*J35,"") | L35: =IF(I35=8,G35*H35*J35,"") | M35: =IF(I35=10,G35*H35*J35,"") | N35: =IF(I35=12,G35*H35*J35,"") | O35: =IF(I35=14,G35*H35*J35,"") | P35: =IF(I35=16,G35*H35*J35,"") | Q35: =IF(I35=20,G35*H35*J35,"") | R35: =IF(I35=25,G35*H35*J35,"") | S35: =IF(I35=32,G35*H35*J35,"")
A36: CADRE | G36: 4 | H36: =ROUNDUP(1.2/0.15,0)+2 | I36: 6 | J36: =(2*(0.3+0.3)-0.05+20.5*I36/1000) | K36: =IF(I36=6,G36*H36*J36,"") | L36: =IF(I36=8,G36*H36*J36,"") | M36: =IF(I36=10,G36*H36*J36,"") | N36: =IF(I36=12,G36*H36*J36,"") | O36: =IF(I36=14,G36*H36*J36,"") | P36: =IF(I36=16,G36*H36*J36,"") | Q36: =IF(I36=20,G36*H36*J36,"") | R36: =IF(I36=25,G36*H36*J36,"") | S36: =IF(I36=32,G36*H36*J36,"")
A37: EPINGLE | G37: 4 | H37: =ROUNDUP(1.2/0.15,0)+2 | I37: 6 | J37: =0.3-0.05+22*I37/1000 | K37: =IF(I37=6,G37*H37*J37,"") | L37: =IF(I37=8,G37*H37*J37,"") | M37: =IF(I37=10,G37*H37*J37,"") | N37: =IF(I37=12,G37*H37*J37,"") | O37: =IF(I37=14,G37*H37*J37,"") | P37: =IF(I37=16,G37*H37*J37,"") | Q37: =IF(I37=20,G37*H37*J37,"") | R37: =IF(I37=25,G37*H37*J37,"") | S37: =IF(I37=32,G37*H37*J37,"")
E38: P4 | K38: =IF(I38=6,G38*H38*J38,"") | L38: =IF(I38=8,G38*H38*J38,"") | M38: =IF(I38=10,G38*H38*J38,"") | N38: =IF(I38=12,G38*H38*J38,"") | O38: =IF(I38=14,G38*H38*J38,"") | P38: =IF(I38=16,G38*H38*J38,"") | Q38: =IF(I38=20,G38*H38*J38,"") | R38: =IF(I38=25,G38*H38*J38,"") | S38: =IF(I38=32,G38*H38*J38,"")
A39: ARM LONG | G39: 2 | H39: 6 | I39: 14 | J39: =($T$22-0.1-0.05)+70*I39/1000+18*I39/1000 | K39: =IF(I39=6,G39*H39*J39,"") | L39: =IF(I39=8,G39*H39*J39,"") | M39: =IF(I39=10,G39*H39*J39,"") | N39: =IF(I39=12,G39*H39*J39,"") | O39: =IF(I39=14,G39*H39*J39,"") | P39: =IF(I39=16,G39*H39*J39,"") | Q39: =IF(I39=20,G39*H39*J39,"") | R39: =IF(I39=25,G39*H39*J39,"") | S39: =IF(I39=32,G39*H39*J39,"")
A40: CADRE | G40: 2 | H40: =ROUNDUP(1.2/0.15,0)+2 | I40: 6 | J40: =(2*(0.35+0.35)-0.05+20.5*I40/1000) | K40: =IF(I40=6,G40*H40*J40,"") | L40: =IF(I40=8,G40*H40*J40,"") | M40: =IF(I40=10,G40*H40*J40,"") | N40: =IF(I40=12,G40*H40*J40,"") | O40: =IF(I40=14,G40*H40*J40,"") | P40: =IF(I40=16,G40*H40*J40,"") | Q40: =IF(I40=20,G40*H40*J40,"") | R40: =IF(I40=25,G40*H40*J40,"") | S40: =IF(I40=32,G40*H40*J40,"")
A41: EPINGLE | G41: 2 | H41: =ROUNDUP(1.2/0.15,0)+2 | I41: 6 | J41: =0.35-0.05+22*I41/1000 | K41: =IF(I41=6,G41*H41*J41,"") | L41: =IF(I41=8,G41*H41*J41,"") | M41: =IF(I41=10,G41*H41*J41,"") | N41: =IF(I41=12,G41*H41*J41,"") | O41: =IF(I41=14,G41*H41*J41,"") | P41: =IF(I41=16,G41*H41*J41,"") | Q41: =IF(I41=20,G41*H41*J41,"") | R41: =IF(I41=25,G41*H41*J41,"") | S41: =IF(I41=32,G41*H41*J41,"")
A42: total | M42: =SUM(L23:L38)
A43: chainage
...

Sheet Comparaison
A1: Comparaison générée vs métré de référence
A2: Poste | B2: Section | C2: Élément | D2: Champ | E2: Référence | F2: Généré | G2: Écart | H2: Commentaire
A4: 15 | B4: longrines_prop | C4: C /5-6 LG | D4: Longueur | E4: 4.8 | F4: 4.78 | G4: -0.02
A5: 15 | B5: longrines_prop | C5: C /5-6 LG | D5: Qté | E5: 0.192 | F5: 0.191 | G5: -0.001
A6: 15 | B6: longrines_prop | C6: 2 /D-G LG2 | D6: Longueur | E6: 5.77 | F6: 5.05 | G6: -0.72
A7: 15 | B7: longrines_prop | C7: 2 /D-G LG2 | D7: Qté | E7: 0.231 | F7: 0.202 | G7: -0.029
A8: 15 | B8: longrines_prop | C8: 3 /D-G LG2 | D8: Longueur | E8: 5.77 | F8: 5.05 | G8: -0.72
A9: 15 | B9: longrines_prop | C9: 3 /D-G LG2 | D9: Qté | E9: 0.231 | F9: 0.202 | G9: -0.029
A10: 16 | B10: gros_beton | C10: S5 F /5 | D10: LIGNE | E10: absente (réf.) | F10: ajoutée (générée) | H10: présente sur le plan / absente du métré de référence
A11: 16 | B11: gros_beton | C11: S5 E /5 | D11: LIGNE | E11: présente (réf.) | F11: non reproduite | H11: du métré de référence — voir rapport
A12: 20 | B12: semelles_ba | C12: S5 F /5 | D12: largeur | E12: 1.3 | F12: 1.5 | G12: 0.2
A13: 20 | B13: semelles_ba | C13: S5 F /5 | D13: Qté | E13: 0.78 | F13: 0.9 | G13: 0.12
A14: 20 | B14: semelles_ba | C14: S4 G /2 | D14: Hauteur | E14: 0.25 | F14: 0.4 | G14: 0.15
A15: 20 | B15: semelles_ba | C15: S4 G /2 | D15: Qté | E15: 0.562 | F15: 0.9 | G15: 0.338
A16: 20 | B16: longrines_ba | C16: 2 /D-G LG2 | D16: Longueur | E16: 5.77 | F16: 5.05 | G16: -0.72
A17: 20 | B17: longrines_ba | C17: 2 /D-G LG2 | D17: Qté | E17: 0.462 | F17: 0.404 | G17: -0.058
A18: 20 | B18: longrines_ba | C18: 3 /D-G LG2 | D18: Longueur | E18: 5.77 | F18: 5.05 | G18: -0.72
A19: 20 | B19: longrines_ba | C19: 3 /D-G LG2 | D19: Qté | E19: 0.462 | F19: 0.404 | G19: -0.058
A20: 20 | B20: poutres_mezz | C20: N4 5 /F-G N4 | D20: LIGNE | E20: absente (réf.) | F20: ajoutée (générée) | H20: présent sur le plan, absent du métré de référence
A21: 20 | B21: poutres_mezz | C21: N3 6 /A-C N3 | D21: Hauteur | E21: 0.45 | F21: 0.4 | G21: -0.05
A22: 20 | B22: poutres_mezz | C22: N3 6 /A-C N3 | D22: Qté | E22: 0.38 | F22: 0.338 | G22: -0.042
A23: 20 | B23: poutres_mezz | C23: N3 7 /A-C N3 | D23: Hauteur | E23: 0.45 | F23: 0.4 | G23: -0.05
A24: 20 | B24: poutres_mezz | C24: N3 7 /A-C N3 | D24: Qté | E24: 0.38 | F24: 0.338 | G24: -0.042
A25: 20 | B25: poutres_mezz | C25: N3 8 /A-C N3 | D25: LIGNE | E25: absente (réf.) | F25: ajoutée (générée) | H25: axe 8 absent du métré de référence
A26: 20 | B26: poutres_mezz | C26: N1 8 /C-E N1 | D26: LIGNE | E26: absente (réf.) | F26: ajoutée (générée) | H26: axe 8 absent du métré de référence
A27: 20 | B27: poutres_mezz | C27: N3 8 /E-G N3 | D27: LIGNE | E27: absente (réf.) | F27: ajoutée (générée) | H27: axe 8 absent du métré de référence
A28: 20 | B28: poutres_mezz | C28: BN2 C /5-6 BN2 | D28: LIGNE | E28: absente (réf.) | F28: ajoutée (générée) | H28: présente sur le plan / absente du métré de référence
A29: 20 | B29: poutres_mezz | C29: BN2 C /6-7 BN2 | D29: LIGNE | E29: absente (réf.) | F29: ajoutée (générée) | H29: présente sur le plan / absente du métré de référence
A30: 20 | B30: poutres_mezz | C30: BN2 C /7-8 BN2 | D30: LIGNE | E30: absente (réf.) | F30: ajoutée (générée) | H30: présente sur le plan / absente du métré de référence
A31: 20 | B31: poutres_mezz | C31: BN2 E /5-6 BN2 | D31: LIGNE | E31: absente (réf.) | F31: ajoutée (générée) | H31: présente sur le plan / absente du métré de référence
A32: 20 | B32: poutres_mezz | C32: BN2 E /6-7 BN2 | D32: LIGNE | E32: absente (réf.) | F32: ajoutée (générée) | H32: présente sur le plan / absente du métré de référence
A33: 20 | B33: poutres_mezz | C33: BN2 E /7-8 BN2 | D33: LIGNE | E33: absente (réf.) | F33: ajoutée (générée) | H33: présente sur le plan / absente du métré de référence
A34: 20 | B34: poutres_mezz | C34: 7 /A-C N3 | D34: LIGNE | E34: présente (réf.) | F34: non reproduite | H34: du métré de référence — voir rapport
A35: 20 | B35: poutres_mezz | C35: 7 /C-E N1 | D35: LIGNE | E35: présente (réf.) | F35: non reproduite | H35: du métré de référence — voir rapport
A36: 20 | B36: poutres_mezz | C36: 7 /E-G N3 | D36: LIGNE | E36: présente (réf.) | F36: non reproduite | H36: du métré de référence — voir rapport
... A42: 20 | B42: poutres_mezz | C42: E /7-8 BN | D42: LIGNE | E42: présente (réf.) | F42: non reproduite | H42: du métré de référence — voir rapport
A43: 20 | B43: poutres_ph | C43: N1 A /1-2 N1 | D43: Longueur | E43: 5.05 | F43: 2.48 | G43: -2.57 | H43: référence : longueur erronée 5.05 au lieu de 2.48
A44: 20 | B44: poutres_ph | C44: N1 A /1-2 N1 | D44: Hauteur | E44: 0.5 | F44: 0.3 | G44: -0.2 | H44: référence : longueur erronée 5.05 au lieu de 2.48
A45: 20 | B45: poutres_ph | C45: N1 A /1-2 N1 | D45: Qté | E45: 0.505 | F45: 0.149 | G45: -0.356 | H45: référence : longueur erronée 5.05 au lieu de 2.48
A46: 20 | B46: poutres_ph | C46: N1 A /6-7 N1 | D46: Longueur | E46: 0.65 | F46: 2.65 | G46: 2 | H46: référence : longueur 0.65 au lieu de 2.65
...
