Workbook

Sheet 01_Detail_Quantitatif
A1: DÉTAIL QUANTITATIF ESTIMATIF — GROS ŒUVRES
A2: N° Marché : | D2: Projet : | E2: Projet extrait | H2: Bâtiment :
A3: Date : | D3: Établi par : | H3: Vérifié par :
A5: DÉTAIL QUANTITATIF — FONDATIONS & ÉLÉVATION
A6: N° | B6: Axe | C6: File | D6: Désignation des Ouvrages | E6: U | F6: N | G6: Longueur (m) | H6: Largeur (m) | I6: Hauteur (m) | J6: Qté Partielle | K6: Qté Totale
A7: 1 | D7: Terrassement en fouilles
B8: Axe | C8: File
B9: A | C9: 5 | D9: Fouille Semelle S2 | E9: M3 | F9: 1 | G9: 1.3 | H9: 1.3 | I9: 1.2 | J9: =IF(COUNTA(G9:I9)>0,F9*PRODUCT(G9:I9),F9)
B10: A | C10: 8 | D10: Fouille Semelle S3 | E10: M3 | F10: 1 | G10: 1.4 | H10: 1.4 | I10: 1.2 | J10: =IF(COUNTA(G10:I10)>0,F10*PRODUCT(G10:I10),F10)
B11: G | C11: 8 | D11: Fouille Semelle S3 | E11: M3 | F11: 1 | G11: 1.4 | H11: 1.4 | I11: 1.2 | J11: =IF(COUNTA(G11:I11)>0,F11*PRODUCT(G11:I11),F11)
B12: G | C12: 7 | D12: Fouille Semelle S3 | E12: M3 | F12: 1 | G12: 1.4 | H12: 1.4 | I12: 1.2 | J12: =IF(COUNTA(G12:I12)>0,F12*PRODUCT(G12:I12),F12)
B13: G | C13: 6 | D13: Fouille Semelle S3 | E13: M3 | F13: 1 | G13: 1.4 | H13: 1.4 | I13: 1.2 | J13: =IF(COUNTA(G13:I13)>0,F13*PRODUCT(G13:I13),F13)
B14: A | C14: 7 | D14: Fouille Semelle S3 | E14: M3 | F14: 1 | G14: 1.4 | H14: 1.4 | I14: 1.2 | J14: =IF(COUNTA(G14:I14)>0,F14*PRODUCT(G14:I14),F14)
B15: A | C15: 6 | D15: Fouille Semelle S3 | E15: M3 | F15: 1 | G15: 1.4 | H15: 1.4 | I15: 1.2 | J15: =IF(COUNTA(G15:I15)>0,F15*PRODUCT(G15:I15),F15)
B16: D | C16: 7 | D16: Fouille Semelle S4 | E16: M3 | F16: 1 | G16: 1.7 | H16: 1.7 | I16: 1.2 | J16: =IF(COUNTA(G16:I16)>0,F16*PRODUCT(G16:I16),F16)
B17: D | C17: 8 | D17: Fouille Semelle S3 | E17: M3 | F17: 1 | G17: 1.4 | H17: 1.4 | I17: 1.2 | J17: =IF(COUNTA(G17:I17)>0,F17*PRODUCT(G17:I17),F17)
B18: B | C18: 8 | D18: Fouille Semelle S3 | E18: M3 | F18: 1 | G18: 1.4 | H18: 1.4 | I18: 1.2 | J18: =IF(COUNTA(G18:I18)>0,F18*PRODUCT(G18:I18),F18)
B19: G | C19: 1 | D19: Fouille Semelle S1 | E19: M3 | F19: 1 | G19: 1.2 | H19: 1.2 | I19: 1.2 | J19: =IF(COUNTA(G19:I19)>0,F19*PRODUCT(G19:I19),F19)
B20: A | C20: 1 | D20: Fouille Semelle S1 | E20: M3 | F20: 1 | G20: 1.2 | H20: 1.2 | I20: 1.2 | J20: =IF(COUNTA(G20:I20)>0,F20*PRODUCT(G20:I20),F20)
... B31: G | C31: 5 | D31: Fouille Semelle S5 | E31: M3 | F31: 1 | G31: 1.7 | H31: 1.7 | I31: 1.2 | J31: =IF(COUNTA(G31:I31)>0,F31*PRODUCT(G31:I31),F31)
A32: Ss-total | J32: =SUM(J9:J31) | K32: =SUM(J9:J31)
A33: 2 | D33: Béton de propreté dosé à 150 kg/m³
B34: Axe | C34: File
B35: A | C35: 5 | D35: BP Semelle S2 | E35: M3 | F35: 1 | G35: 1.2 | H35: 1.2 | I35: 0.1 | J35: =IF(COUNTA(G35:I35)>0,F35*PRODUCT(G35:I35),F35)
B36: A | C36: 8 | D36: BP Semelle S3 | E36: M3 | F36: 1 | G36: 1.3 | H36: 1.3 | I36: 0.1 | J36: =IF(COUNTA(G36:I36)>0,F36*PRODUCT(G36:I36),F36)
B37: G | C37: 8 | D37: BP Semelle S3 | E37: M3 | F37: 1 | G37: 1.3 | H37: 1.3 | I37: 0.1 | J37: =IF(COUNTA(G37:I37)>0,F37*PRODUCT(G37:I37),F37)
B38: G | C38: 7 | D38: BP Semelle S3 | E38: M3 | F38: 1 | G38: 1.3 | H38: 1.3 | I38: 0.1 | J38: =IF(COUNTA(G38:I38)>0,F38*PRODUCT(G38:I38),F38)
B39: G | C39: 6 | D39: BP Semelle S3 | E39: M3 | F39: 1 | G39: 1.3 | H39: 1.3 | I39: 0.1 | J39: =IF(COUNTA(G39:I39)>0,F39*PRODUCT(G39:I39),F39)
B40: A | C40: 7 | D40: BP Semelle S3 | E40: M3 | F40: 1 | G40: 1.3 | H40: 1.3 | I40: 0.1 | J40: =IF(COUNTA(G40:I40)>0,F40*PRODUCT(G40:I40),F40)
B41: A | C41: 6 | D41: BP Semelle S3 | E41: M3 | F41: 1 | G41: 1.3 | H41: 1.3 | I41: 0.1 | J41: =IF(COUNTA(G41:I41)>0,F41*PRODUCT(G41:I41),F41)
B42: D | C42: 7 | D42: BP Semelle S4 | E42: M3 | F42: 1 | G42: 1.6 | H42: 1.6 | I42: 0.1 | J42: =IF(COUNTA(G42:I42)>0,F42*PRODUCT(G42:I42),F42)
B43: D | C43: 8 | D43: BP Semelle S3 | E43: M3 | F43: 1 | G43: 1.3 | H43: 1.3 | I43: 0.1 | J43: =IF(COUNTA(G43:I43)>0,F43*PRODUCT(G43:I43),F43)
B44: B | C44: 8 | D44: BP Semelle S3 | E44: M3 | F44: 1 | G44: 1.3 | H44: 1.3 | I44: 0.1 | J44: =IF(COUNTA(G44:I44)>0,F44*PRODUCT(G44:I44),F44)
B45: G | C45: 1 | D45: BP Semelle S1 | E45: M3 | F45: 1 | G45: 1.1 | H45: 1.1 | I45: 0.1 | J45: =IF(COUNTA(G45:I45)>0,F45*PRODUCT(G45:I45),F45)
B46: A | C46: 1 | D46: BP Semelle S1 | E46: M3 | F46: 1 | G46: 1.1 | H46: 1.1 | I46: 0.1 | J46: =IF(COUNTA(G46:I46)>0,F46*PRODUCT(G46:I46),F46)
... B57: G | C57: 5 | D57: BP Semelle S5 | E57: M3 | F57: 1 | G57: 1.6 | H57: 1.6 | I57: 0.1 | J57: =IF(COUNTA(G57:I57)>0,F57*PRODUCT(G57:I57),F57)
A58: Ss-total | J58: =SUM(J35:J57) | K58: =SUM(J35:J57)
A59: 3 | D59: Béton armé en fondation dosé à 350 kg/m³
B60: Axe | C60: File
B61: A | C61: 5 | D61: Semelle S2 | E61: M3 | F61: 1 | G61: 1.1 | H61: 1.1 | I61: 0.25 | J61: =IF(COUNTA(G61:I61)>0,F61*PRODUCT(G61:I61),F61)
...

Sheet 02_Armatures
A1: NOMENCLATURE ET DÉCORTICAGE DÉTAILLÉ DES ARMATURES
A2: Projet : | K2: Date : | O2: Indice :
A3: Repère / Ouvrage | B3: Axe | C3: File | D3: a (m) | E3: b (m) | F3: h (m) | G3: N° ELE | H3: NOMB B | I3: DIAM | J3: LONG (m) | K3: T6 | L3: T8 | M3: T10 | N3: T12 | O3: T14 | P3: T16 | Q3: T20 | R3: T25 | S3: T32
A4: S2 | B4: A | C4: 5 | D4: 1.1 | E4: 1.1 | F4: 0.25 | K4: =IF($I4=6,$G4*$H4*$J4,"") | L4: =IF($I4=8,$G4*$H4*$J4,"") | M4: =IF($I4=10,$G4*$H4*$J4,"") | N4: =IF($I4=12,$G4*$H4*$J4,"") | O4: =IF($I4=14,$G4*$H4*$J4,"") | P4: =IF($I4=16,$G4*$H4*$J4,"") | Q4: =IF($I4=20,$G4*$H4*$J4,"") | R4: =IF($I4=25,$G4*$H4*$J4,"") | S4: =IF($I4=32,$G4*$H4*$J4,"")
A5: Armature INF X | G5: 1 | H5: 7 | I5: 12 | J5: =(E4-0.05)+34*I5/1000 | K5: =IF($I5=6,$G5*$H5*$J5,"") | L5: =IF($I5=8,$G5*$H5*$J5,"") | M5: =IF($I5=10,$G5*$H5*$J5,"") | N5: =IF($I5=12,$G5*$H5*$J5,"") | O5: =IF($I5=14,$G5*$H5*$J5,"") | P5: =IF($I5=16,$G5*$H5*$J5,"") | Q5: =IF($I5=20,$G5*$H5*$J5,"") | R5: =IF($I5=25,$G5*$H5*$J5,"") | S5: =IF($I5=32,$G5*$H5*$J5,"")
A6: Armature INF Y | G6: 1 | H6: 7 | I6: 12 | J6: =(D4-0.05)+34*I6/1000 | K6: =IF($I6=6,$G6*$H6*$J6,"") | L6: =IF($I6=8,$G6*$H6*$J6,"") | M6: =IF($I6=10,$G6*$H6*$J6,"") | N6: =IF($I6=12,$G6*$H6*$J6,"") | O6: =IF($I6=14,$G6*$H6*$J6,"") | P6: =IF($I6=16,$G6*$H6*$J6,"") | Q6: =IF($I6=20,$G6*$H6*$J6,"") | R6: =IF($I6=25,$G6*$H6*$J6,"") | S6: =IF($I6=32,$G6*$H6*$J6,"")
A7: S3 | B7: A | C7: 8 | D7: 1.2 | E7: 1.2 | F7: 0.3 | K7: =IF($I7=6,$G7*$H7*$J7,"") | L7: =IF($I7=8,$G7*$H7*$J7,"") | M7: =IF($I7=10,$G7*$H7*$J7,"") | N7: =IF($I7=12,$G7*$H7*$J7,"") | O7: =IF($I7=14,$G7*$H7*$J7,"") | P7: =IF($I7=16,$G7*$H7*$J7,"") | Q7: =IF($I7=20,$G7*$H7*$J7,"") | R7: =IF($I7=25,$G7*$H7*$J7,"") | S7: =IF($I7=32,$G7*$H7*$J7,"")
A8: Armature INF X | G8: 1 | H8: 8 | I8: 12 | J8: =(E7-0.05)+34*I8/1000 | K8: =IF($I8=6,$G8*$H8*$J8,"") | L8: =IF($I8=8,$G8*$H8*$J8,"") | M8: =IF($I8=10,$G8*$H8*$J8,"") | N8: =IF($I8=12,$G8*$H8*$J8,"") | O8: =IF($I8=14,$G8*$H8*$J8,"") | P8: =IF($I8=16,$G8*$H8*$J8,"") | Q8: =IF($I8=20,$G8*$H8*$J8,"") | R8: =IF($I8=25,$G8*$H8*$J8,"") | S8: =IF($I8=32,$G8*$H8*$J8,"")
A9: Armature INF Y | G9: 1 | H9: 8 | I9: 12 | J9: =(D7-0.05)+34*I9/1000 | K9: =IF($I9=6,$G9*$H9*$J9,"") | L9: =IF($I9=8,$G9*$H9*$J9,"") | M9: =IF($I9=10,$G9*$H9*$J9,"") | N9: =IF($I9=12,$G9*$H9*$J9,"") | O9: =IF($I9=14,$G9*$H9*$J9,"") | P9: =IF($I9=16,$G9*$H9*$J9,"") | Q9: =IF($I9=20,$G9*$H9*$J9,"") | R9: =IF($I9=25,$G9*$H9*$J9,"") | S9: =IF($I9=32,$G9*$H9*$J9,"")
A10: S3 | B10: G | C10: 8 | D10: 1.2 | E10: 1.2 | F10: 0.3 | K10: =IF($I10=6,$G10*$H10*$J10,"") | L10: =IF($I10=8,$G10*$H10*$J10,"") | M10: =IF($I10=10,$G10*$H10*$J10,"") | N10: =IF($I10=12,$G10*$H10*$J10,"") | O10: =IF($I10=14,$G10*$H10*$J10,"") | P10: =IF($I10=16,$G10*$H10*$J10,"") | Q10: =IF($I10=20,$G10*$H10*$J10,"") | R10: =IF($I10=25,$G10*$H10*$J10,"") | S10: =IF($I10=32,$G10*$H10*$J10,"")
A11: Armature INF X | G11: 1 | H11: 8 | I11: 12 | J11: =(E10-0.05)+34*I11/1000 | K11: =IF($I11=6,$G11*$H11*$J11,"") | L11: =IF($I11=8,$G11*$H11*$J11,"") | M11: =IF($I11=10,$G11*$H11*$J11,"") | N11: =IF($I11=12,$G11*$H11*$J11,"") | O11: =IF($I11=14,$G11*$H11*$J11,"") | P11: =IF($I11=16,$G11*$H11*$J11,"") | Q11: =IF($I11=20,$G11*$H11*$J11,"") | R11: =IF($I11=25,$G11*$H11*$J11,"") | S11: =IF($I11=32,$G11*$H11*$J11,"")
A12: Armature INF Y | G12: 1 | H12: 8 | I12: 12 | J12: =(D10-0.05)+34*I12/1000 | K12: =IF($I12=6,$G12*$H12*$J12,"") | L12: =IF($I12=8,$G12*$H12*$J12,"") | M12: =IF($I12=10,$G12*$H12*$J12,"") | N12: =IF($I12=12,$G12*$H12*$J12,"") | O12: =IF($I12=14,$G12*$H12*$J12,"") | P12: =IF($I12=16,$G12*$H12*$J12,"") | Q12: =IF($I12=20,$G12*$H12*$J12,"") | R12: =IF($I12=25,$G12*$H12*$J12,"") | S12: =IF($I12=32,$G12*$H12*$J12,"")
A13: S3 | B13: G | C13: 7 | D13: 1.2 | E13: 1.2 | F13: 0.3 | K13: =IF($I13=6,$G13*$H13*$J13,"") | L13: =IF($I13=8,$G13*$H13*$J13,"") | M13: =IF($I13=10,$G13*$H13*$J13,"") | N13: =IF($I13=12,$G13*$H13*$J13,"") | O13: =IF($I13=14,$G13*$H13*$J13,"") | P13: =IF($I13=16,$G13*$H13*$J13,"") | Q13: =IF($I13=20,$G13*$H13*$J13,"") | R13: =IF($I13=25,$G13*$H13*$J13,"") | S13: =IF($I13=32,$G13*$H13*$J13,"")
A14: Armature INF X | G14: 1 | H14: 8 | I14: 12 | J14: =(E13-0.05)+34*I14/1000 | K14: =IF($I14=6,$G14*$H14*$J14,"") | L14: =IF($I14=8,$G14*$H14*$J14,"") | M14: =IF($I14=10,$G14*$H14*$J14,"") | N14: =IF($I14=12,$G14*$H14*$J14,"") | O14: =IF($I14=14,$G14*$H14*$J14,"") | P14: =IF($I14=16,$G14*$H14*$J14,"") | Q14: =IF($I14=20,$G14*$H14*$J14,"") | R14: =IF($I14=25,$G14*$H14*$J14,"") | S14: =IF($I14=32,$G14*$H14*$J14,"")
A15: Armature INF Y | G15: 1 | H15: 8 | I15: 12 | J15: =(D13-0.05)+34*I15/1000 | K15: =IF($I15=6,$G15*$H15*$J15,"") | L15: =IF($I15=8,$G15*$H15*$J15,"") | M15: =IF($I15=10,$G15*$H15*$J15,"") | N15: =IF($I15=12,$G15*$H15*$J15,"") | O15: =IF($I15=14,$G15*$H15*$J15,"") | P15: =IF($I15=16,$G15*$H15*$J15,"") | Q15: =IF($I15=20,$G15*$H15*$J15,"") | R15: =IF($I15=25,$G15*$H15*$J15,"") | S15: =IF($I15=32,$G15*$H15*$J15,"")
A16: S3 | B16: G | C16: 6 | D16: 1.2 | E16: 1.2 | F16: 0.3 | K16: =IF($I16=6,$G16*$H16*$J16,"") | L16: =IF($I16=8,$G16*$H16*$J16,"") | M16: =IF($I16=10,$G16*$H16*$J16,"") | N16: =IF($I16=12,$G16*$H16*$J16,"") | O16: =IF($I16=14,$G16*$H16*$J16,"") | P16: =IF($I16=16,$G16*$H16*$J16,"") | Q16: =IF($I16=20,$G16*$H16*$J16,"") | R16: =IF($I16=25,$G16*$H16*$J16,"") | S16: =IF($I16=32,$G16*$H16*$J16,"")
A17: Armature INF X | G17: 1 | H17: 8 | I17: 12 | J17: =(E16-0.05)+34*I17/1000 | K17: =IF($I17=6,$G17*$H17*$J17,"") | L17: =IF($I17=8,$G17*$H17*$J17,"") | M17: =IF($I17=10,$G17*$H17*$J17,"") | N17: =IF($I17=12,$G17*$H17*$J17,"") | O17: =IF($I17=14,$G17*$H17*$J17,"") | P17: =IF($I17=16,$G17*$H17*$J17,"") | Q17: =IF($I17=20,$G17*$H17*$J17,"") | R17: =IF($I17=25,$G17*$H17*$J17,"") | S17: =IF($I17=32,$G17*$H17*$J17,"")
A18: Armature INF Y | G18: 1 | H18: 8 | I18: 12 | J18: =(D16-0.05)+34*I18/1000 | K18: =IF($I18=6,$G18*$H18*$J18,"") | L18: =IF($I18=8,$G18*$H18*$J18,"") | M18: =IF($I18=10,$G18*$H18*$J18,"") | N18: =IF($I18=12,$G18*$H18*$J18,"") | O18: =IF($I18=14,$G18*$H18*$J18,"") | P18: =IF($I18=16,$G18*$H18*$J18,"") | Q18: =IF($I18=20,$G18*$H18*$J18,"") | R18: =IF($I18=25,$G18*$H18*$J18,"") | S18: =IF($I18=32,$G18*$H18*$J18,"")
A19: S3 | B19: A | C19: 7 | D19: 1.2 | E19: 1.2 | F19: 0.3 | K19: =IF($I19=6,$G19*$H19*$J19,"") | L19: =IF($I19=8,$G19*$H19*$J19,"") | M19: =IF($I19=10,$G19*$H19*$J19,"") | N19: =IF($I19=12,$G19*$H19*$J19,"") | O19: =IF($I19=14,$G19*$H19*$J19,"") | P19: =IF($I19=16,$G19*$H19*$J19,"") | Q19: =IF($I19=20,$G19*$H19*$J19,"") | R19: =IF($I19=25,$G19*$H19*$J19,"") | S19: =IF($I19=32,$G19*$H19*$J19,"")
A20: Armature INF X | G20: 1 | H20: 8 | I20: 12 | J20: =(E19-0.05)+34*I20/1000 | K20: =IF($I20=6,$G20*$H20*$J20,"") | L20: =IF($I20=8,$G20*$H20*$J20,"") | M20: =IF($I20=10,$G20*$H20*$J20,"") | N20: =IF($I20=12,$G20*$H20*$J20,"") | O20: =IF($I20=14,$G20*$H20*$J20,"") | P20: =IF($I20=16,$G20*$H20*$J20,"") | Q20: =IF($I20=20,$G20*$H20*$J20,"") | R20: =IF($I20=25,$G20*$H20*$J20,"") | S20: =IF($I20=32,$G20*$H20*$J20,"")
A21: Armature INF Y | G21: 1 | H21: 8 | I21: 12 | J21: =(D19-0.05)+34*I21/1000 | K21: =IF($I21=6,$G21*$H21*$J21,"") | L21: =IF($I21=8,$G21*$H21*$J21,"") | M21: =IF($I21=10,$G21*$H21*$J21,"") | N21: =IF($I21=12,$G21*$H21*$J21,"") | O21: =IF($I21=14,$G21*$H21*$J21,"") | P21: =IF($I21=16,$G21*$H21*$J21,"") | Q21: =IF($I21=20,$G21*$H21*$J21,"") | R21: =IF($I21=25,$G21*$H21*$J21,"") | S21: =IF($I21=32,$G21*$H21*$J21,"")
A22: S3 | B22: A | C22: 6 | D22: 1.2 | E22: 1.2 | F22: 0.3 | K22: =IF($I22=6,$G22*$H22*$J22,"") | L22: =IF($I22=8,$G22*$H22*$J22,"") | M22: =IF($I22=10,$G22*$H22*$J22,"") | N22: =IF($I22=12,$G22*$H22*$J22,"") | O22: =IF($I22=14,$G22*$H22*$J22,"") | P22: =IF($I22=16,$G22*$H22*$J22,"") | Q22: =IF($I22=20,$G22*$H22*$J22,"") | R22: =IF($I22=25,$G22*$H22*$J22,"") | S22: =IF($I22=32,$G22*$H22*$J22,"")
A23: Armature INF X | G23: 1 | H23: 8 | I23: 12 | J23: =(E22-0.05)+34*I23/1000 | K23: =IF($I23=6,$G23*$H23*$J23,"") | L23: =IF($I23=8,$G23*$H23*$J23,"") | M23: =IF($I23=10,$G23*$H23*$J23,"") | N23: =IF($I23=12,$G23*$H23*$J23,"") | O23: =IF($I23=14,$G23*$H23*$J23,"") | P23: =IF($I23=16,$G23*$H23*$J23,"") | Q23: =IF($I23=20,$G23*$H23*$J23,"") | R23: =IF($I23=25,$G23*$H23*$J23,"") | S23: =IF($I23=32,$G23*$H23*$J23,"")
A24: Armature INF Y | G24: 1 | H24: 8 | I24: 12 | J24: =(D22-0.05)+34*I24/1000 | K24: =IF($I24=6,$G24*$H24*$J24,"") | L24: =IF($I24=8,$G24*$H24*$J24,"") | M24: =IF($I24=10,$G24*$H24*$J24,"") | N24: =IF($I24=12,$G24*$H24*$J24,"") | O24: =IF($I24=14,$G24*$H24*$J24,"") | P24: =IF($I24=16,$G24*$H24*$J24,"") | Q24: =IF($I24=20,$G24*$H24*$J24,"") | R24: =IF($I24=25,$G24*$H24*$J24,"") | S24: =IF($I24=32,$G24*$H24*$J24,"")
A25: S4 | B25: D | C25: 7 | D25: 1.5 | E25: 1.5 | F25: 0.4 | K25: =IF($I25=6,$G25*$H25*$J25,"") | L25: =IF($I25=8,$G25*$H25*$J25,"") | M25: =IF($I25=10,$G25*$H25*$J25,"") | N25: =IF($I25=12,$G25*$H25*$J25,"") | O25: =IF($I25=14,$G25*$H25*$J25,"") | P25: =IF($I25=16,$G25*$H25*$J25,"") | Q25: =IF($I25=20,$G25*$H25*$J25,"") | R25: =IF($I25=25,$G25*$H25*$J25,"") | S25: =IF($I25=32,$G25*$H25*$J25,"")
A26: Armature INF X | G26: 1 | H26: 11 | I26: 12 | J26: =(E25-0.05)+34*I26/1000 | K26: =IF($I26=6,$G26*$H26*$J26,"") | L26: =IF($I26=8,$G26*$H26*$J26,"") | M26: =IF($I26=10,$G26*$H26*$J26,"") | N26: =IF($I26=12,$G26*$H26*$J26,"") | O26: =IF($I26=14,$G26*$H26*$J26,"") | P26: =IF($I26=16,$G26*$H26*$J26,"") | Q26: =IF($I26=20,$G26*$H26*$J26,"") | R26: =IF($I26=25,$G26*$H26*$J26,"") | S26: =IF($I26=32,$G26*$H26*$J26,"")
A27: Armature INF Y | G27: 1 | H27: 11 | I27: 12 | J27: =(D25-0.05)+34*I27/1000 | K27: =IF($I27=6,$G27*$H27*$J27,"") | L27: =IF($I27=8,$G27*$H27*$J27,"") | M27: =IF($I27=10,$G27*$H27*$J27,"") | N27: =IF($I27=12,$G27*$H27*$J27,"") | O27: =IF($I27=14,$G27*$H27*$J27,"") | P27: =IF($I27=16,$G27*$H27*$J27,"") | Q27: =IF($I27=20,$G27*$H27*$J27,"") | R27: =IF($I27=25,$G27*$H27*$J27,"") | S27: =IF($I27=32,$G27*$H27*$J27,"")
A28: S3 | B28: D | C28: 8 | D28: 1.2 | E28: 1.2 | F28: 0.3 | K28: =IF($I28=6,$G28*$H28*$J28,"") | L28: =IF($I28=8,$G28*$H28*$J28,"") | M28: =IF($I28=10,$G28*$H28*$J28,"") | N28: =IF($I28=12,$G28*$H28*$J28,"") | O28: =IF($I28=14,$G28*$H28*$J28,"") | P28: =IF($I28=16,$G28*$H28*$J28,"") | Q28: =IF($I28=20,$G28*$H28*$J28,"") | R28: =IF($I28=25,$G28*$H28*$J28,"") | S28: =IF($I28=32,$G28*$H28*$J28,"")
A29: Armature INF X | G29: 1 | H29: 8 | I29: 12 | J29: =(E28-0.05)+34*I29/1000 | K29: =IF($I29=6,$G29*$H29*$J29,"") | L29: =IF($I29=8,$G29*$H29*$J29,"") | M29: =IF($I29=10,$G29*$H29*$J29,"") | N29: =IF($I29=12,$G29*$H29*$J29,"") | O29: =IF($I29=14,$G29*$H29*$J29,"") | P29: =IF($I29=16,$G29*$H29*$J29,"") | Q29: =IF($I29=20,$G29*$H29*$J29,"") | R29: =IF($I29=25,$G29*$H29*$J29,"") | S29: =IF($I29=32,$G29*$H29*$J29,"")
A30: Armature INF Y | G30: 1 | H30: 8 | I30: 12 | J30: =(D28-0.05)+34*I30/1000 | K30: =IF($I30=6,$G30*$H30*$J30,"") | L30: =IF($I30=8,$G30*$H30*$J30,"") | M30: =IF($I30=10,$G30*$H30*$J30,"") | N30: =IF($I30=12,$G30*$H30*$J30,"") | O30: =IF($I30=14,$G30*$H30*$J30,"") | P30: =IF($I30=16,$G30*$H30*$J30,"") | Q30: =IF($I30=20,$G30*$H30*$J30,"") | R30: =IF($I30=25,$G30*$H30*$J30,"") | S30: =IF($I30=32,$G30*$H30*$J30,"")
A31: S3 | B31: B | C31: 8 | D31: 1.2 | E31: 1.2 | F31: 0.3 | K31: =IF($I31=6,$G31*$H31*$J31,"") | L31: =IF($I31=8,$G31*$H31*$J31,"") | M31: =IF($I31=10,$G31*$H31*$J31,"") | N31: =IF($I31=12,$G31*$H31*$J31,"") | O31: =IF($I31=14,$G31*$H31*$J31,"") | P31: =IF($I31=16,$G31*$H31*$J31,"") | Q31: =IF($I31=20,$G31*$H31*$J31,"") | R31: =IF($I31=25,$G31*$H31*$J31,"") | S31: =IF($I31=32,$G31*$H31*$J31,"")
A32: Armature INF X | G32: 1 | H32: 8 | I32: 12 | J32: =(E31-0.05)+34*I32/1000 | K32: =IF($I32=6,$G32*$H32*$J32,"") | L32: =IF($I32=8,$G32*$H32*$J32,"") | M32: =IF($I32=10,$G32*$H32*$J32,"") | N32: =IF($I32=12,$G32*$H32*$J32,"") | O32: =IF($I32=14,$G32*$H32*$J32,"") | P32: =IF($I32=16,$G32*$H32*$J32,"") | Q32: =IF($I32=20,$G32*$H32*$J32,"") | R32: =IF($I32=25,$G32*$H32*$J32,"") | S32: =IF($I32=32,$G32*$H32*$J32,"")
A33: Armature INF Y | G33: 1 | H33: 8 | I33: 12 | J33: =(D31-0.05)+34*I33/1000 | K33: =IF($I33=6,$G33*$H33*$J33,"") | L33: =IF($I33=8,$G33*$H33*$J33,"") | M33: =IF($I33=10,$G33*$H33*$J33,"") | N33: =IF($I33=12,$G33*$H33*$J33,"") | O33: =IF($I33=14,$G33*$H33*$J33,"") | P33: =IF($I33=16,$G33*$H33*$J33,"") | Q33: =IF($I33=20,$G33*$H33*$J33,"") | R33: =IF($I33=25,$G33*$H33*$J33,"") | S33: =IF($I33=32,$G33*$H33*$J33,"")
A34: S1 | B34: G | C34: 1 | D34: 1 | E34: 1 | F34: 0.25 | K34: =IF($I34=6,$G34*$H34*$J34,"") | L34: =IF($I34=8,$G34*$H34*$J34,"") | M34: =IF($I34=10,$G34*$H34*$J34,"") | N34: =IF($I34=12,$G34*$H34*$J34,"") | O34: =IF($I34=14,$G34*$H34*$J34,"") | P34: =IF($I34=16,$G34*$H34*$J34,"") | Q34: =IF($I34=20,$G34*$H34*$J34,"") | R34: =IF($I34=25,$G34*$H34*$J34,"") | S34: =IF($I34=32,$G34*$H34*$J34,"")
A35: Armature INF X | G35: 1 | H35: 6 | I35: 12 | J35: =(E34-0.05)+34*I35/1000 | K35: =IF($I35=6,$G35*$H35*$J35,"") | L35: =IF($I35=8,$G35*$H35*$J35,"") | M35: =IF($I35=10,$G35*$H35*$J35,"") | N35: =IF($I35=12,$G35*$H35*$J35,"") | O35: =IF($I35=14,$G35*$H35*$J35,"") | P35: =IF($I35=16,$G35*$H35*$J35,"") | Q35: =IF($I35=20,$G35*$H35*$J35,"") | R35: =IF($I35=25,$G35*$H35*$J35,"") | S35: =IF($I35=32,$G35*$H35*$J35,"")
A36: Armature INF Y | G36: 1 | H36: 6 | I36: 12 | J36: =(D34-0.05)+34*I36/1000 | K36: =IF($I36=6,$G36*$H36*$J36,"") | L36: =IF($I36=8,$G36*$H36*$J36,"") | M36: =IF($I36=10,$G36*$H36*$J36,"") | N36: =IF($I36=12,$G36*$H36*$J36,"") | O36: =IF($I36=14,$G36*$H36*$J36,"") | P36: =IF($I36=16,$G36*$H36*$J36,"") | Q36: =IF($I36=20,$G36*$H36*$J36,"") | R36: =IF($I36=25,$G36*$H36*$J36,"") | S36: =IF($I36=32,$G36*$H36*$J36,"")
A37: S1 | B37: A | C37: 1 | D37: 1 | E37: 1 | F37: 0.25 | K37: =IF($I37=6,$G37*$H37*$J37,"") | L37: =IF($I37=8,$G37*$H37*$J37,"") | M37: =IF($I37=10,$G37*$H37*$J37,"") | N37: =IF($I37=12,$G37*$H37*$J37,"") | O37: =IF($I37=14,$G37*$H37*$J37,"") | P37: =IF($I37=16,$G37*$H37*$J37,"") | Q37: =IF($I37=20,$G37*$H37*$J37,"") | R37: =IF($I37=25,$G37*$H37*$J37,"") | S37: =IF($I37=32,$G37*$H37*$J37,"")
A38: Armature INF X | G38: 1 | H38: 6 | I38: 12 | J38: =(E37-0.05)+34*I38/1000 | K38: =IF($I38=6,$G38*$H38*$J38,"") | L38: =IF($I38=8,$G38*$H38*$J38,"") | M38: =IF($I38=10,$G38*$H38*$J38,"") | N38: =IF($I38=12,$G38*$H38*$J38,"") | O38: =IF($I38=14,$G38*$H38*$J38,"") | P38: =IF($I38=16,$G38*$H38*$J38,"") | Q38: =IF($I38=20,$G38*$H38*$J38,"") | R38: =IF($I38=25,$G38*$H38*$J38,"") | S38: =IF($I38=32,$G38*$H38*$J38,"")
A39: Armature INF Y | G39: 1 | H39: 6 | I39: 12 | J39: =(D37-0.05)+34*I39/1000 | K39: =IF($I39=6,$G39*$H39*$J39,"") | L39: =IF($I39=8,$G39*$H39*$J39,"") | M39: =IF($I39=10,$G39*$H39*$J39,"") | N39: =IF($I39=12,$G39*$H39*$J39,"") | O39: =IF($I39=14,$G39*$H39*$J39,"") | P39: =IF($I39=16,$G39*$H39*$J39,"") | Q39: =IF($I39=20,$G39*$H39*$J39,"") | R39: =IF($I39=25,$G39*$H39*$J39,"") | S39: =IF($I39=32,$G39*$H39*$J39,"")
A40: S5 | B40: F | C40: 5 | D40: 1.5 | E40: 1.5 | F40: 0.4 | K40: =IF($I40=6,$G40*$H40*$J40,"") | L40: =IF($I40=8,$G40*$H40*$J40,"") | M40: =IF($I40=10,$G40*$H40*$J40,"") | N40: =IF($I40=12,$G40*$H40*$J40,"") | O40: =IF($I40=14,$G40*$H40*$J40,"") | P40: =IF($I40=16,$G40*$H40*$J40,"") | Q40: =IF($I40=20,$G40*$H40*$J40,"") | R40: =IF($I40=25,$G40*$H40*$J40,"") | S40: =IF($I40=32,$G40*$H40*$J40,"")
...

Sheet 03_Attachement_Ferraillage
A1: ATTACHEMENT — SYNTHÈSE DES ARMATURES PAR TYPE D'OUVRAGE
A2: Projet : | F2: Attachement n° : | J2: Date :
A3: Type d'Ouvrage | B3: Type d'Armature | C3: N° Ouvrages cumulés | D3: Nb barres | E3: Diamètre (mm) | F3: Longueur unitaire (m) | G3: T6 | H3: T8 | I3: T10 | J3: T12 | K3: T14 | L3: T16 | M3: T20 | N3: T25 | O3: T32
A4: Semelle S2 | B4: Lit INF X & Y | C4: 1 | D4: 14 | E4: 12 | F4: 1.458 | G4: =IF($E4=6,$C4*$D4*$F4,"") | H4: =IF($E4=8,$C4*$D4*$F4,"") | I4: =IF($E4=10,$C4*$D4*$F4,"") | J4: =IF($E4=12,$C4*$D4*$F4,"") | K4: =IF($E4=14,$C4*$D4*$F4,"") | L4: =IF($E4=16,$C4*$D4*$F4,"") | M4: =IF($E4=20,$C4*$D4*$F4,"") | N4: =IF($E4=25,$C4*$D4*$F4,"") | O4: =IF($E4=32,$C4*$D4*$F4,"")
A5: Semelle S3 | B5: Lit INF X & Y | C5: 1 | D5: 16 | E5: 12 | F5: 1.558 | G5: =IF($E5=6,$C5*$D5*$F5,"") | H5: =IF($E5=8,$C5*$D5*$F5,"") | I5: =IF($E5=10,$C5*$D5*$F5,"") | J5: =IF($E5=12,$C5*$D5*$F5,"") | K5: =IF($E5=14,$C5*$D5*$F5,"") | L5: =IF($E5=16,$C5*$D5*$F5,"") | M5: =IF($E5=20,$C5*$D5*$F5,"") | N5: =IF($E5=25,$C5*$D5*$F5,"") | O5: =IF($E5=32,$C5*$D5*$F5,"")
A6: Semelle S3 | B6: Lit INF X & Y | C6: 1 | D6: 16 | E6: 12 | F6: 1.558 | G6: =IF($E6=6,$C6*$D6*$F6,"") | H6: =IF($E6=8,$C6*$D6*$F6,"") | I6: =IF($E6=10,$C6*$D6*$F6,"") | J6: =IF($E6=12,$C6*$D6*$F6,"") | K6: =IF($E6=14,$C6*$D6*$F6,"") | L6: =IF($E6=16,$C6*$D6*$F6,"") | M6: =IF($E6=20,$C6*$D6*$F6,"") | N6: =IF($E6=25,$C6*$D6*$F6,"") | O6: =IF($E6=32,$C6*$D6*$F6,"")
A7: Semelle S3 | B7: Lit INF X & Y | C7: 1 | D7: 16 | E7: 12 | F7: 1.558 | G7: =IF($E7=6,$C7*$D7*$F7,"") | H7: =IF($E7=8,$C7*$D7*$F7,"") | I7: =IF($E7=10,$C7*$D7*$F7,"") | J7: =IF($E7=12,$C7*$D7*$F7,"") | K7: =IF($E7=14,$C7*$D7*$F7,"") | L7: =IF($E7=16,$C7*$D7*$F7,"") | M7: =IF($E7=20,$C7*$D7*$F7,"") | N7: =IF($E7=25,$C7*$D7*$F7,"") | O7: =IF($E7=32,$C7*$D7*$F7,"")
A8: Semelle S3 | B8: Lit INF X & Y | C8: 1 | D8: 16 | E8: 12 | F8: 1.558 | G8: =IF($E8=6,$C8*$D8*$F8,"") | H8: =IF($E8=8,$C8*$D8*$F8,"") | I8: =IF($E8=10,$C8*$D8*$F8,"") | J8: =IF($E8=12,$C8*$D8*$F8,"") | K8: =IF($E8=14,$C8*$D8*$F8,"") | L8: =IF($E8=16,$C8*$D8*$F8,"") | M8: =IF($E8=20,$C8*$D8*$F8,"") | N8: =IF($E8=25,$C8*$D8*$F8,"") | O8: =IF($E8=32,$C8*$D8*$F8,"")
A9: Semelle S3 | B9: Lit INF X & Y | C9: 1 | D9: 16 | E9: 12 | F9: 1.558 | G9: =IF($E9=6,$C9*$D9*$F9,"") | H9: =IF($E9=8,$C9*$D9*$F9,"") | I9: =IF($E9=10,$C9*$D9*$F9,"") | J9: =IF($E9=12,$C9*$D9*$F9,"") | K9: =IF($E9=14,$C9*$D9*$F9,"") | L9: =IF($E9=16,$C9*$D9*$F9,"") | M9: =IF($E9=20,$C9*$D9*$F9,"") | N9: =IF($E9=25,$C9*$D9*$F9,"") | O9: =IF($E9=32,$C9*$D9*$F9,"")
A10: Semelle S3 | B10: Lit INF X & Y | C10: 1 | D10: 16 | E10: 12 | F10: 1.558 | G10: =IF($E10=6,$C10*$D10*$F10,"") | H10: =IF($E10=8,$C10*$D10*$F10,"") | I10: =IF($E10=10,$C10*$D10*$F10,"") | J10: =IF($E10=12,$C10*$D10*$F10,"") | K10: =IF($E10=14,$C10*$D10*$F10,"") | L10: =IF($E10=16,$C10*$D10*$F10,"") | M10: =IF($E10=20,$C10*$D10*$F10,"") | N10: =IF($E10=25,$C10*$D10*$F10,"") | O10: =IF($E10=32,$C10*$D10*$F10,"")
A11: Semelle S4 | B11: Lit INF X & Y | C11: 1 | D11: 22 | E11: 12 | F11: 1.858 | G11: =IF($E11=6,$C11*$D11*$F11,"") | H11: =IF($E11=8,$C11*$D11*$F11,"") | I11: =IF($E11=10,$C11*$D11*$F11,"") | J11: =IF($E11=12,$C11*$D11*$F11,"") | K11: =IF($E11=14,$C11*$D11*$F11,"") | L11: =IF($E11=16,$C11*$D11*$F11,"") | M11: =IF($E11=20,$C11*$D11*$F11,"") | N11: =IF($E11=25,$C11*$D11*$F11,"") | O11: =IF($E11=32,$C11*$D11*$F11,"")
A12: Semelle S3 | B12: Lit INF X & Y | C12: 1 | D12: 16 | E12: 12 | F12: 1.558 | G12: =IF($E12=6,$C12*$D12*$F12,"") | H12: =IF($E12=8,$C12*$D12*$F12,"") | I12: =IF($E12=10,$C12*$D12*$F12,"") | J12: =IF($E12=12,$C12*$D12*$F12,"") | K12: =IF($E12=14,$C12*$D12*$F12,"") | L12: =IF($E12=16,$C12*$D12*$F12,"") | M12: =IF($E12=20,$C12*$D12*$F12,"") | N12: =IF($E12=25,$C12*$D12*$F12,"") | O12: =IF($E12=32,$C12*$D12*$F12,"")
A13: Semelle S3 | B13: Lit INF X & Y | C13: 1 | D13: 16 | E13: 12 | F13: 1.558 | G13: =IF($E13=6,$C13*$D13*$F13,"") | H13: =IF($E13=8,$C13*$D13*$F13,"") | I13: =IF($E13=10,$C13*$D13*$F13,"") | J13: =IF($E13=12,$C13*$D13*$F13,"") | K13: =IF($E13=14,$C13*$D13*$F13,"") | L13: =IF($E13=16,$C13*$D13*$F13,"") | M13: =IF($E13=20,$C13*$D13*$F13,"") | N13: =IF($E13=25,$C13*$D13*$F13,"") | O13: =IF($E13=32,$C13*$D13*$F13,"")
A14: Semelle S1 | B14: Lit INF X & Y | C14: 1 | D14: 12 | E14: 12 | F14: 1.358 | G14: =IF($E14=6,$C14*$D14*$F14,"") | H14: =IF($E14=8,$C14*$D14*$F14,"") | I14: =IF($E14=10,$C14*$D14*$F14,"") | J14: =IF($E14=12,$C14*$D14*$F14,"") | K14: =IF($E14=14,$C14*$D14*$F14,"") | L14: =IF($E14=16,$C14*$D14*$F14,"") | M14: =IF($E14=20,$C14*$D14*$F14,"") | N14: =IF($E14=25,$C14*$D14*$F14,"") | O14: =IF($E14=32,$C14*$D14*$F14,"")
A15: Semelle S1 | B15: Lit INF X & Y | C15: 1 | D15: 12 | E15: 12 | F15: 1.358 | G15: =IF($E15=6,$C15*$D15*$F15,"") | H15: =IF($E15=8,$C15*$D15*$F15,"") | I15: =IF($E15=10,$C15*$D15*$F15,"") | J15: =IF($E15=12,$C15*$D15*$F15,"") | K15: =IF($E15=14,$C15*$D15*$F15,"") | L15: =IF($E15=16,$C15*$D15*$F15,"") | M15: =IF($E15=20,$C15*$D15*$F15,"") | N15: =IF($E15=25,$C15*$D15*$F15,"") | O15: =IF($E15=32,$C15*$D15*$F15,"")
... A30: Poteau P4 | B30: ARM LONG | C30: 1 | D30: 6 | E30: 14 | F30: 3.5 | G30: =IF($E30=6,$C30*$D30*$F30,"") | H30: =IF($E30=8,$C30*$D30*$F30,"") | I30: =IF($E30=10,$C30*$D30*$F30,"") | J30: =IF($E30=12,$C30*$D30*$F30,"") | K30: =IF($E30=14,$C30*$D30*$F30,"") | L30: =IF($E30=16,$C30*$D30*$F30,"") | M30: =IF($E30=20,$C30*$D30*$F30,"") | N30: =IF($E30=25,$C30*$D30*$F30,"") | O30: =IF($E30=32,$C30*$D30*$F30,"")
A31: Poutre BN1 | B31: Filants | C31: 1 | D31: 2 | E31: 12 | G31: =IF($E31=6,$C31*$D31*$F31,"") | H31: =IF($E31=8,$C31*$D31*$F31,"") | I31: =IF($E31=10,$C31*$D31*$F31,"") | J31: =IF($E31=12,$C31*$D31*$F31,"") | K31: =IF($E31=14,$C31*$D31*$F31,"") | L31: =IF($E31=16,$C31*$D31*$F31,"") | M31: =IF($E31=20,$C31*$D31*$F31,"") | N31: =IF($E31=25,$C31*$D31*$F31,"") | O31: =IF($E31=32,$C31*$D31*$F31,"")
A32: Poutre BN1 | B32: Filants | C32: 1 | D32: 4 | E32: 14 | G32: =IF($E32=6,$C32*$D32*$F32,"") | H32: =IF($E32=8,$C32*$D32*$F32,"") | I32: =IF($E32=10,$C32*$D32*$F32,"") | J32: =IF($E32=12,$C32*$D32*$F32,"") | K32: =IF($E32=14,$C32*$D32*$F32,"") | L32: =IF($E32=16,$C32*$D32*$F32,"") | M32: =IF($E32=20,$C32*$D32*$F32,"") | N32: =IF($E32=25,$C32*$D32*$F32,"") | O32: =IF($E32=32,$C32*$D32*$F32,"")
A33: Poutre BN1 | B33: Filants | C33: 1 | D33: 4 | E33: 16 | G33: =IF($E33=6,$C33*$D33*$F33,"") | H33: =IF($E33=8,$C33*$D33*$F33,"") | I33: =IF($E33=10,$C33*$D33*$F33,"") | J33: =IF($E33=12,$C33*$D33*$F33,"") | K33: =IF($E33=14,$C33*$D33*$F33,"") | L33: =IF($E33=16,$C33*$D33*$F33,"") | M33: =IF($E33=20,$C33*$D33*$F33,"") | N33: =IF($E33=25,$C33*$D33*$F33,"") | O33: =IF($E33=32,$C33*$D33*$F33,"")
A34: Poutre BN1 | B34: Filants | C34: 1 | D34: 4 | E34: 12 | G34: =IF($E34=6,$C34*$D34*$F34,"") | H34: =IF($E34=8,$C34*$D34*$F34,"") | I34: =IF($E34=10,$C34*$D34*$F34,"") | J34: =IF($E34=12,$C34*$D34*$F34,"") | K34: =IF($E34=14,$C34*$D34*$F34,"") | L34: =IF($E34=16,$C34*$D34*$F34,"") | M34: =IF($E34=20,$C34*$D34*$F34,"") | N34: =IF($E34=25,$C34*$D34*$F34,"") | O34: =IF($E34=32,$C34*$D34*$F34,"")
A35: Poutre BN1 | B35: Filants | C35: 1 | D35: 4 | E35: 14 | G35: =IF($E35=6,$C35*$D35*$F35,"") | H35: =IF($E35=8,$C35*$D35*$F35,"") | I35: =IF($E35=10,$C35*$D35*$F35,"") | J35: =IF($E35=12,$C35*$D35*$F35,"") | K35: =IF($E35=14,$C35*$D35*$F35,"") | L35: =IF($E35=16,$C35*$D35*$F35,"") | M35: =IF($E35=20,$C35*$D35*$F35,"") | N35: =IF($E35=25,$C35*$D35*$F35,"") | O35: =IF($E35=32,$C35*$D35*$F35,"")
A36: Poutre BN1 | B36: Filants | C36: 1 | D36: 2 | E36: 12 | G36: =IF($E36=6,$C36*$D36*$F36,"") | H36: =IF($E36=8,$C36*$D36*$F36,"") | I36: =IF($E36=10,$C36*$D36*$F36,"") | J36: =IF($E36=12,$C36*$D36*$F36,"") | K36: =IF($E36=14,$C36*$D36*$F36,"") | L36: =IF($E36=16,$C36*$D36*$F36,"") | M36: =IF($E36=20,$C36*$D36*$F36,"") | N36: =IF($E36=25,$C36*$D36*$F36,"") | O36: =IF($E36=32,$C36*$D36*$F36,"")
A37: Poutre BN1 | B37: Filants | C37: 1 | D37: 2 | E37: 16 | G37: =IF($E37=6,$C37*$D37*$F37,"") | H37: =IF($E37=8,$C37*$D37*$F37,"") | I37: =IF($E37=10,$C37*$D37*$F37,"") | J37: =IF($E37=12,$C37*$D37*$F37,"") | K37: =IF($E37=14,$C37*$D37*$F37,"") | L37: =IF($E37=16,$C37*$D37*$F37,"") | M37: =IF($E37=20,$C37*$D37*$F37,"") | N37: =IF($E37=25,$C37*$D37*$F37,"") | O37: =IF($E37=32,$C37*$D37*$F37,"")
A38: Poutre N1 | B38: Filants | C38: 1 | D38: 2 | E38: 10 | G38: =IF($E38=6,$C38*$D38*$F38,"") | H38: =IF($E38=8,$C38*$D38*$F38,"") | I38: =IF($E38=10,$C38*$D38*$F38,"") | J38: =IF($E38=12,$C38*$D38*$F38,"") | K38: =IF($E38=14,$C38*$D38*$F38,"") | L38: =IF($E38=16,$C38*$D38*$F38,"") | M38: =IF($E38=20,$C38*$D38*$F38,"") | N38: =IF($E38=25,$C38*$D38*$F38,"") | O38: =IF($E38=32,$C38*$D38*$F38,"")
A39: Poutre N1 | B39: Filants | C39: 1 | D39: 2 | E39: 12 | G39: =IF($E39=6,$C39*$D39*$F39,"") | H39: =IF($E39=8,$C39*$D39*$F39,"") | I39: =IF($E39=10,$C39*$D39*$F39,"") | J39: =IF($E39=12,$C39*$D39*$F39,"") | K39: =IF($E39=14,$C39*$D39*$F39,"") | L39: =IF($E39=16,$C39*$D39*$F39,"") | M39: =IF($E39=20,$C39*$D39*$F39,"") | N39: =IF($E39=25,$C39*$D39*$F39,"") | O39: =IF($E39=32,$C39*$D39*$F39,"")
A40: Poutre N1 | B40: Filants | C40: 1 | D40: 2 | E40: 12 | G40: =IF($E40=6,$C40*$D40*$F40,"") | H40: =IF($E40=8,$C40*$D40*$F40,"") | I40: =IF($E40=10,$C40*$D40*$F40,"") | J40: =IF($E40=12,$C40*$D40*$F40,"") | K40: =IF($E40=14,$C40*$D40*$F40,"") | L40: =IF($E40=16,$C40*$D40*$F40,"") | M40: =IF($E40=20,$C40*$D40*$F40,"") | N40: =IF($E40=25,$C40*$D40*$F40,"") | O40: =IF($E40=32,$C40*$D40*$F40,"")
A41: Poutre N2 | B41: Filants | C41: 1 | D41: 2 | E41: 10 | G41: =IF($E41=6,$C41*$D41*$F41,"") | H41: =IF($E41=8,$C41*$D41*$F41,"") | I41: =IF($E41=10,$C41*$D41*$F41,"") | J41: =IF($E41=12,$C41*$D41*$F41,"") | K41: =IF($E41=14,$C41*$D41*$F41,"") | L41: =IF($E41=16,$C41*$D41*$F41,"") | M41: =IF($E41=20,$C41*$D41*$F41,"") | N41: =IF($E41=25,$C41*$D41*$F41,"") | O41: =IF($E41=32,$C41*$D41*$F41,"")
A42: Poutre N2 | B42: Filants | C42: 1 | D42: 2 | E42: 12 | G42: =IF($E42=6,$C42*$D42*$F42,"") | H42: =IF($E42=8,$C42*$D42*$F42,"") | I42: =IF($E42=10,$C42*$D42*$F42,"") | J42: =IF($E42=12,$C42*$D42*$F42,"") | K42: =IF($E42=14,$C42*$D42*$F42,"") | L42: =IF($E42=16,$C42*$D42*$F42,"") | M42: =IF($E42=20,$C42*$D42*$F42,"") | N42: =IF($E42=25,$C42*$D42*$F42,"") | O42: =IF($E42=32,$C42*$D42*$F42,"")
... A59: Poutre N7 | B59: Filants | C59: 1 | D59: 4 | E59: 14 | G59: =IF($E59=6,$C59*$D59*$F59,"") | H59: =IF($E59=8,$C59*$D59*$F59,"") | I59: =IF($E59=10,$C59*$D59*$F59,"") | J59: =IF($E59=12,$C59*$D59*$F59,"") | K59: =IF($E59=14,$C59*$D59*$F59,"") | L59: =IF($E59=16,$C59*$D59*$F59,"") | M59: =IF($E59=20,$C59*$D59*$F59,"") | N59: =IF($E59=25,$C59*$D59*$F59,"") | O59: =IF($E59=32,$C59*$D59*$F59,"")
A60: LONGUEUR TOTALE (ml) | G60: =SUM(G4:G59) | H60: =SUM(H4:H59) | I60: =SUM(I4:I59) | J60: =SUM(J4:J59) | K60: =SUM(K4:K59) | L60: =SUM(L4:L59) | M60: =SUM(M4:M59) | N60: =SUM(N4:N59) | O60: =SUM(O4:O59)
A61: POIDS TOTAL SYNTHÈSE (kg) | G61: =G60*0.222+H60*0.395+I60*0.617+J60*0.888+K60*1.208+L60*1.578+M60*2.466+N60*3.853+O60*6.313

Sheet 04_GO_Attachement
A1: ATTACHEMENT — GROS ŒUVRES & DÉCOMPTE DES QUANTITÉS
A2: N° Marché : | C2: Situation n° : | E2: Période :
A3: N° Prix | B3: Désignation des Travaux | C3: Unité | D3: Qté Marché | E3: Qté Réalisée | F3: Reste | G3: % Avancement
A4: 1 | B4: Terrassement en fouilles | C4: M3 | E4: ='01_Detail_Quantitatif'!K32 | F4: =D4-E4 | G4: =IF(D4>0,E4/D4,0)
A5: 2 | B5: Béton de propreté dosé à 150 kg/m³ | C5: M3 | E5: ='01_Detail_Quantitatif'!K58 | F5: =D5-E5 | G5: =IF(D5>0,E5/D5,0)
A6: 3 | B6: Béton armé en fondation et élévation dosé à 350 kg/m³ | C6: M3 | E6: ='01_Detail_Quantitatif'!K84 | F6: =D6-E6 | G6: =IF(D6>0,E6/D6,0)
A7: 4 | B7: Aciers Haute Adhérence FeE500 | C7: KG | E7: ='02_Armatures'!K126 | F7: =D7-E7 | G7: =IF(D7>0,E7/D7,0)
A8: 5 | B8: Béton pour fûts de poteaux en fondation | C8: M3 | E8: ='01_Detail_Quantitatif'!K91 | F8: =D8-E8 | G8: =IF(D8>0,E8/D8,0)

Sheet 05_Catalogue_Armatures_Standard
A1: RÉFÉRENTIEL TECHNIQUE — CATALOGUE DES ARMATURES STANDARDISÉES (FIMUREX / EUROCODE 2)
A2: Abaques de dimensionnement, sections d'acier, charges admissibles et nomenclatures de chantier
A4: 1. POTEAUX PRÉFABRIQUÉS STANDARD (FIMUREX PN - 4 ET 6 FILANTS, H <= 2.80 m)
A5: Réf. Armature | B5: Type | C5: Section Béton (cm) | D5: Aciers Filants | E5: Cadres / Espac. | F5: Pser Intérieur (daN) | G5: Pser Extérieur (daN) | H5: Pser Int. (kN) | I5: Pser Ext. (kN) | J5: Attente PA | K5: Domaine / Norme
A6: PN4108X8 | B6: Type I | C6: 15 x 15 | D6: 4 HA 10 | E6: HA 5 e=15 | F6: 11780 | G6: 19500 | H6: 117.8 | I6: 195 | J6: PA4108X8 | K6: Eurocode 2 / Non sismique
A7: PN41010X10 | B7: Type I | C7: 15 x 15 | D7: 4 HA 10 | E7: HA 5 e=15 | F7: 11840 | G7: 25650 | H7: 118.4 | I7: 256.5 | J7: PA41010X10 | K7: Eurocode 2 / Non sismique
A8: PN41015X15 | B8: Type I | C8: 20 x 20 | D8: 4 HA 10 | E8: HA 5 e=15 | F8: 25810 | G8: 45180 | H8: 258.1 | I8: 451.8 | J8: PA1015X15 | K8: Eurocode 2 / Non sismique
A9: PN41020X20 | B9: Type I | C9: 25 x 25 | D9: 4 HA 10 | E9: HA 5 e=15 | F9: 45320 | G9: 70840 | H9: 453.2 | I9: 708.4 | J9: PA1015X15 | K9: Eurocode 2 / Non sismique
A10: P6N41025X25 | B10: Type I | C10: 30 x 30 | D10: 4 HA 10 | E10: HA 5 e=15 | F10: 70960 | G10: 97560 | H10: 709.6 | I10: 975.6 | J10: Sur mesure | K10: Eurocode 2 / Non sismique
A11: PN41010X20 | B11: Type I | C11: 15 x 25 | D11: 4 HA 10 | E11: HA 5 e=15 | F11: 17770 | G11: 36470 | H11: 177.7 | I11: 364.7 | J11: PA41010X10 | K11: Eurocode 2 / Section rect.
A12: PN41015X20 | B12: Type I | C12: 20 x 25 | D12: 4 HA 10 | E12: HA 5 e=15 | F12: 31210 | G12: 53230 | H12: 312.1 | I12: 532.3 | J12: PA1015X15 | K12: Eurocode 2 / Section rect.
A13: P6N61015X30 | B13: Type III | C13: 20 x 35 | D13: 6 HA 10 | E13: HA 5 e=15 | F13: 42010 | G13: 69330 | H13: 420.1 | I13: 693.3 | J13: PA661010X25 | K13: Eurocode 2 / 6 filants
A14: P6N61015X40 | B14: Type III | C14: 20 x 45 | D14: 6 HA 10 | E14: HA 5 e=15 | F14: 52820 | G14: 85430 | H14: 528.2 | I14: 854.3 | J14: PA661010X35 | K14: Eurocode 2 / 6 filants
A16: 2. SEMELLES ISOLÉES SOUS POTEAUX (FIMUREX SIC CARRÉES)
A17: Réf. Armature | B17: Section AxAxH (cm) | C17: Pser à 1.0 bar (daN) | D17: Pser à 1.5 bar (daN) | E17: Pser à 2.0 bars (daN) | F17: Pser 1.5b (kN) | G17: Nappes Inf. X | H17: Nappes Inf. Y | I17: Crochets (e cm) | J17: Abouts (cm) | K17: Enrobage (cm)
A18: SIC4655 / 4855 | B18: 65 x 65 x 20 | C18: 4230 | D18: 6340 | E18: 8450 | F18: 63.4 | G18: 4 HA 8 | H18: 4 HA 8 | I18: e = 15 | J18: 5 | K18: 5
A19: SIC5775 | B19: 85 x 85 x 25 | C19: 7230 | D19: 10840 | E19: 14450 | F19: 108.4 | G19: 5 HA 8 | H19: 5 HA 8 | I19: e = 15 | J19: 5 | K19: 5
A20: SIC6895 | B20: 105 x 105 x 30 | C20: 11030 | D20: 16540 | E20: 22050 | F20: 165.4 | G20: 6 HA 8 | H20: 6 HA 8 | I20: e = 15 | J20: 5 | K20: 5
A21: SIC610115 | B21: 125 x 125 x 35 | C21: 15630 | D21: 23440 | E21: 31250 | F21: 234.4 | G21: 6 HA 10 | H21: 6 HA 10 | I21: e = 15 | J21: 5 | K21: 5
A22: SIC710135 | B22: 145 x 145 x 40 | C22: 21030 | D22: 31540 | E22: 38090 | F22: 315.4 | G22: 7 HA 10 | H22: 7 HA 10 | I22: e = 15 | J22: 5 | K22: 5
A24: 3. SEMELLES FILANTES PLATES & RENFORCÉES (FIMUREX S / F / FM - Lg = 6.00 m)
A25: Réf. Armature | B25: Type Ouvrage | C25: Largeur (cm) | D25: Hauteur (cm) | E25: Aciers Filants | F25: Armatures Transv. | G25: Espac. (cm) | H25: Nuance Acier | I25: Conditionnement | J25: Usage Sol Recommandé | K25: Conformité
A26: S3835 | B26: Semelle plate | C26: 35 | D26: 5 | E26: 3 HA 8 | F26: Crochets HA 5 | G26: e = 30 | H26: B500A / B500B | I26: 48 unités | J26: Sol homogène sans tassement | K26: EC2 / FD P18-717
A27: S31040 | B27: Semelle plate | C27: 40 | D27: 5 | E27: 3 HA 10 | F27: Crochets HA 5 | G27: e = 30 | H27: B500A / B500B | I27: 48 unités | J27: Sol homogène standard | K27: EC2 / FD P18-717
A28: S41050 | B28: Semelle plate | C28: 50 | D28: 5 | E28: 4 HA 10 | F28: Crochets HA 5 | G28: e = 30 | H28: B500A / B500B | I28: 48 unités | J28: Murs porteurs lourds | K28: EC2 / FD P18-717
A29: F6835X15 | B29: Semelle renforcée | C29: 35 | D29: 15 | E29: 6 HA 8 (2 nappes) | F29: Cadres HA 5 | G29: e = 30 | H29: B500B | I29: 8 unités | J29: Faibles tassements diff. | K29: EC2 / FD P18-717
A30: F6835X20 | B30: Semelle renforcée | C30: 35 | D30: 20 | E30: 6 HA 8 (2 nappes) | F30: Cadres HA 5 | G30: e = 30 | H30: B500B | I30: 6 unités | J30: Faibles tassements diff. | K30: EC2 / FD P18-717
A31: FM61035X20 | B31: Semelle renforcée | C31: 35 | D31: 20 | E31: 6 HA 10 (2 nappes) | F31: Cadres HA 5 | G31: e = 25 | H31: B500B | I31: 6 unités | J31: Charges élevées | K31: EC2 / FD P18-717
A32: FM612140X20 | B32: Semelle renforcée | C32: 40 | D32: 20 | E32: 4 HA 12 + 2 HA 10 | F32: Cadres HA 5 | G32: e = 25 | H32: B500B | I32: 6 unités | J32: Rigidité renforcée | K32: EC2 / FD P18-717
A34: 4. CHAÎNAGES HORIZONTAUX & VERTICAUX (DTU 20.1 & ZONE SISMIQUE Z1 À Z4)
A35: Réf. Armature | B35: Zone Sismique | C35: Section Béton (cm) | D35: Aciers Filants | E35: Section An (cm²) | F35: Armat. Transversales | G35: Espac. (cm) | H35: Fermeture Cadres | I35: Positionnement Nœud | J35: Application | K35: Règle Normative
A36: CH2104X10 | B36: Z1 - Z2 (Très faible / Faible) | C36: 15 x 20 | D36: 2 HA 10 | E36: 1.57 | F36: Épingles Ø 4 | G36: e = 30 à 50 | H36: Libre | I36: - | J36: Chaînage horizontal / pignon | K36: DTU 20.1 (An >= 1.50 cm²)
A37: CH4710X10 | B37: Z1 - Z2 (Très faible / Faible) | C37: 15 x 15 | D37: 4 HA 7 | E37: 1.54 | F37: Cadres Ø 4 | G37: e = 30 à 40 | H37: Libre | I37: - | J37: Chaînage horizontal / vertical | K37: DTU 20.1 (An >= 1.50 cm²)
A38: CH4815X15 | B38: Z1 - Z2 (Très faible / Faible) | C38: 20 x 20 | D38: 4 HA 8 | E38: 2.01 | F38: Cadres Ø 4 | G38: e = 30 à 40 | H38: Libre | I38: - | J38: Chaînage niveaux courants | K38: DTU 20.1 (An >= 1.50 cm²)
A39: CHR41010X10 | B39: Z1 - Z2 (Très faible / Faible) | C39: 20 x 20 | D39: 4 HA 10 | E39: 3.14 | F39: Cadres HA 5 | G39: e = 20 | H39: 135° ou soudé | I39: - | J39: Planchers-terrasses | K39: DTU 20.1 (An >= 3.08 cm²)
A40: CS108X8 | B40: Z3 - Z4 (Modérée / Moyenne) | C40: 15 x 15 min | D40: 4 HA 10 | E40: 3.14 | F40: Cadres HA 5 | G40: e = 15 | H40: Crochets 135° | I40: 1er cadre à <= 7.5 cm | J40: Chaînage vert. / horiz. sismique | K40: CPMI EC8 / EC8-1
A41: CS1210X10 | B41: Z3 - Z4 (Modérée / Moyenne) | C41: 20 x 20 min | D41: 4 HA 12 | E41: 4.52 | F41: Cadres HA 5 | G41: e = 15 | H41: Crochets 135° | I41: 1er cadre à <= 7.5 cm | J41: Chaînage vert. / horiz. sismique | K41: CPMI EC8 / EC8-1
A42: ATCS108X8 | B42: Z3 - Z4 (Modérée / Moyenne) | C42: 15 x 15 min | D42: 4 HA 10 | E42: 3.14 | F42: Cadres HA 5 | G42: 25-4x15-85 | H42: Crochets 135° | I42: Recouvrement >= 60 cm | J42: Attente soubassement sismique | K42: CPMI EC8 (HA10 >= 60 cm)
A43: ATCS128X8 | B43: Z3 - Z4 (Modérée / Moyenne) | C43: 15 x 15 min | D43: 4 HA 12 | E43: 4.52 | F43: Cadres HA 5 | G43: 25-4x15-105 | H43: Crochets 135° | I43: Recouvrement >= 72 cm | J43: Attente soubassement sismique | K43: CPMI EC8 (HA12 >= 72 cm)
A45: 5. POUTRES À HAUTE RÉSISTANCE MANUPORTABLES (FIMUREX VULCAIN & DEMETER)
...
